#include <iostream>
#include <exception> // bibliotheque exception qui contient class exception

using namespace std;
class Test{
public:

static int tableau[] ; // declaration du tableau de type static
public :
static int division(int indice, int diviseur){ // declaration du fonction de type static qui fait la division
return  tableau[indice]/diviseur;
}
};
class MyException : public exception{ // class d'exception
public:
const char * what() const throw()
{
return "le diviseur ne doit pas etre nul \n";
}
};
class MyException2 : public exception{
public:
const char * what() const throw()
{
return "l'indice doit etre compris entre 0 et9 \n"  ;
}
};int Test::tableau[] = {17, 12, 15, 38, 29, 157, 89, -22, 0, 5} ;

int main()

 {
    try
{
int x, y;
cout << "Entrez l indice de l entier a diviser: " << endl;
cin >> x ;
cout << "Entrez le diviseur: " << endl;
cin >> y ;

 if (y == 0)
{  MyException z;
throw z;// renvoie l'objet z de type  MyException
}
else if (x > 9 || x<0){

  MyException2 z;
throw z;  // renvoie l'objet z de type  MyException2

}
else{  cout << "Le résultat de la division est: "<< endl; // terminé avec succès affichage resulltat
        cout <<Test::division(x,y) << endl;}}
catch(exception& e)
{
cout << e.what(); // affiche l'exception
}
return 0;
}


